Workbook

Sheet Schema_v5
A1: Category | B1: Name | C1: Value | D1: Notes
A2: Normalization | B2: SCORE_WEIGHT_MIN | C2: 3 | D2: AnswerBank_v4 score_weight min
A3: Normalization | B3: SCORE_WEIGHT_MAX | C3: 10 | D3: AnswerBank_v4 score_weight max
A4: Normalization | B4: COMP_WEIGHT_MIN | C4: 4 | D4: AnswerBank_v4 compatibility_weight min
A5: Normalization | B5: COMP_WEIGHT_MAX | C5: 10 | D5: AnswerBank_v4 compatibility_weight max
A6: Normalization | B6: READINESS_MAX | C6: 10 | D6: readiness_points_v3 scale
A7: Normalization | B7: STANCE_MAX | C7: 10 | D7: compatibility_stance_v3 scale
A8: Normalization | B8: FORECAST_MAX | C8: 10 | D8: forecast_points_v3 scale
A9: Normalization | B9: PATTERN_RISK_MAX | C9: 1.8 | D9: pattern_risk max in AnswerBank
A10: Normalization | B10: CLUSTER_PENALTY_MAX_PER_ANSWER | C10: 14 | D10: cluster_penalty_points max per answer
A11: Normalization | B11: POL_MASC_MIN | C11: -0.4 | D11: polarity_masc_delta_v3 min
A12: Normalization | B12: POL_MASC_MAX | C12: 1.8 | D12: polarity_masc_delta_v3 max
A13: Normalization | B13: POL_FEM_MIN | C13: -1.6 | D13: polarity_fem_delta_v3 min
... A35: Bonuses/Penalties | B35: HARD_PENALTY_MAX | C35: 0.18 | D35: Normalized adjustment

Sheet MatchEngine_v5
A1: Metric | B1: Value | C1: Notes
A2: ArchetypeNorm | B2: =IFERROR(((0.50*VLOOKUP(FinalScores_v5!E4&"|"&FinalScores_v5!E6,ArchetypeLookup_v4!$A$2:$B$101,2,FALSE)+0.20*VLOOKUP(FinalScores_v5!E4&"|"&FinalScores_v5!E7,ArchetypeLookup_v4!$A$2:$B$101,2,FALSE)+0.20*VLOOKUP(FinalScores_v5!E5&"|"&FinalScores_v5!E6,ArchetypeLookup_v4!$A$2:$B$101,2,FALSE)+0.10*VLOOKUP(FinalScores_v5!E5&"|"&FinalScores_v5!E7,ArchetypeLookup_v4!$A$2:$B$101,2,FALSE))-2)/7,0.5) | C2: Archetype pairing normalized from 2–9 to 0–1
A3: CommNorm | B3: =IFERROR((VLOOKUP(FinalScores_v5!E16,CommLookup_v4!$A$2:$B$16,2,FALSE)-2)/7,0.5) | C3: Communication style (normalized)
A4: RegNorm | B4: =IFERROR((VLOOKUP(FinalScores_v5!E17,RegLookup_v4!$A$2:$B$11,2,FALSE)-3)/7,0.5) | C4: Regulation style (normalized)
A5: LoveNorm | B5: =IFERROR((VLOOKUP(FinalScores_v5!E18,LoveLookup_v4!$A$2:$B$16,2,FALSE)-5)/5,0.6) | C5: Love language fit proxy (normalized)
A6: Readiness_A | B6: =TestHarness_v4!B64 | C6: 0–100
A7: Readiness_B | B7: =TestHarness_v4!B65 | C7: 0–100
A8: ReadinessPairNorm | B8: =MAX(0,((B6+B7)/200) - 0.25*ABS(B6-B7)/100) | C8: Average minus mismatch penalty
A9: ForecastNormPair | B9: =IFERROR((SUMPRODUCT(TestHarness_v4!$B$10:$B$59,TestHarness_v4!$H$10:$H$59)+SUMPRODUCT(TestHarness_v4!$B$10:$B$59,TestHarness_v4!$L$10:$L$59))/(2*SUM(TestHarness_v4!$B$10:$B$59)*Schema_v5!$C$8),0.5) | C9: Weighted forecast points normalized
A10: ClusterPenaltyPairRaw | B10: =MIN(35,0.35*(FinalScores_v5!B5+FinalScores_v5!B6)) | C10: Same as v4 cap
A11: ClusterPenaltyNorm | B11: =MIN(1,B10/35) | C11: 0–1
A12: IntegrityPenaltyRaw | B12: =FinalScores_v5!E40 | C12: 0–80 current logic
A13: IntegrityPenaltyNorm | B13: =MIN(1,B12/80) | C13: 0–1
A14: ShadowRiskRaw | B14: =(TestHarness_v4!B83+TestHarness_v4!B84)/2 | C14: Average shadow intensity
A15: ShadowRiskNorm | B15: =MIN(1,MAX(0,B14/10)) | C15: Assumes 0–10 scale
A16: AttractionPatternNorm | B16: =0.5 | C16: Neutral until you build attraction-pattern model
A17: PolarityNorm | B17: =FinalScores_v5!E35 | C17: Current polarity placeholder (0–1)
A18: ZodiacNorm | B18: =FinalScores_v5!E31 | C18: From AstrologyLookup_v5 zodiac_norm
A19: NumerologyNorm | B19: =FinalScores_v5!E33 | C19: From NumerologyLookup_v5 adjusted_numerology_norm
A20: BehavioralCore | B20: =Schema_v5!$C$15*(Schema_v5!$C$19*B2+Schema_v5!$C$20*B3+Schema_v5!$C$21*B4+Schema_v5!$C$22*B5+Schema_v5!$C$23*B8) | C20: Includes BehavioralCore weight (0.52) * inner mix
A21: StabilityCore | B21: =Schema_v5!$C$16*(Schema_v5!$C$24*(1-B15)+Schema_v5!$C$25*(1-B13)+Schema_v5!$C$26*(1-B11)+Schema_v5!$C$27*B9) | C21: Includes Stability weight (0.23) * inner mix
A22: ChemistryCore | B22: =Schema_v5!$C$17*(Schema_v5!$C$28*B18+Schema_v5!$C$29*B17) | C22: Includes Chemistry weight (0.13) * inner mix
A23: CosmicCore | B23: =Schema_v5!$C$18*(Schema_v5!$C$30*B19+Schema_v5!$C$31*B20) | C23: Includes Cosmic weight (0.12) * inner mix
A24: InteractionBonus | B24: =0 | C24: Normalized -0.06..+0.06 (hook your InteractionRules)
A25: HardPenalty | B25: =0 | C25: Normalized 0..0.18 (severe contradiction / dangerous pair)
A26: RawMatch | B26: =MAX(0,MIN(1,B22+B23+B24+B25 + B26 - B27)) | C26: Clamped 0–1
A27: CompatibilityScore_350_850 | B27: =350+500*B28 | C27: Headline score
A28: StabilityScore_0_100 | B28: =100*(B23/Schema_v5!$C$16) | C28: Remove outer weight to show stability itself
A29: ChemistryScore_0_100 | B29: =100*(B24/Schema_v5!$C$17) | C29: Remove outer weight to show chemistry itself
A30: CosmicOverlayScore_0_100 | B30: =100*(B25/Schema_v5!$C$18) | C30: Remove outer weight to show cosmic overlay itself
A31: TierLabel | B31: =IF(AND(B29>=750,B30>=72,B31>=60),"Soul-aligned",IF(AND(B29>=670,B29<=749,B30>=58),"Strong potential",IF(AND(B29>=650,B31>=75,B30<58),"Magnetic but risky",IF(AND(B29>=560,B29<=669),"Possible but unstable",IF(OR(B29<560,B30<40),"Red flag zone","Unclassified"))))) | C31: Uses the tier logic you specified
A32: TierReasonPrimary | B32: ="Top driver: "&IF(B30<58,"Stability","Compatibility") | C32: Simple placeholder; refine later
A33: TierReasonSecondary | B33: ="Watch: "&IF(B15>0.5,"Shadow activation","Pace/needs mismatch") | C33: Simple placeholder; refine later

Sheet README_v4
A1: Genesis OS v4.1 — Deterministic Scoring Workbook (Full formulas, pre-user-data)
A3: Sheets:
A4: • TestHarness_v4 → enter answer_ids for two users (Q1–Q60). Computes readiness + BehaviorCore + penalties.
A5: • FinalScores_v4 → computes Compatibility 350–850 and Forecast 0–100 using all matrices + the v4 deterministic formula.
A7: Rule: Q1–Q50 count toward readiness/behavior. Q51–Q60 are shadow/integrity only.

Sheet AnswerBank_v4
A1: answer_id | B1: canonical_q | C1: question_number_int | D1: phase | E1: question_weight_v3 | F1: dimension_primary | G1: dimension_secondary | H1: question_text | I1: answer_option_id | J1: answer_letter | K1: answer_text | L1: score_weight | M1: compatibility_weight | N1: readiness_points_v3 | O1: compatibility_stance_v3 | P1: forecast_points_v3 | Q1: archetype | R1: archetype_id | S1: shadow_type | T1: shadow_type_id | U1: shadow_risk_points_v3 | V1: polarity_tag | W1: polarity_masc_delta_v3 | X1: polarity_fem_delta_v3 | Y1: comm_style | Z1: regulation_style | AA1: love_language | AB1: cluster_tags | AC1: cluster_1 | AD1: cluster_2 | AE1: cluster_penalty_points | AF1: pattern_tag | AG1: match_behavior_tag | AH1: pattern_risk | AI1: consistency_flag | AJ1: integrity_flag_v3 | AK1: drift_relevance | AL1: forecast_relevance | AM1: energy_type_tag | AN1: emotion_family | AO1: emotion_cell | AP1: version_snapshot
A2: Q01_A | B2: 1 | C2: 1 | D2: Core | E2: 1 | F2: CommunicationHealth | G2: EmotionalNeeds | H2: When something feels off between you and someone you're dating, what usually happens next-internally or outwardly? | I2: A | J2: A | K2: It's probably nothing. I just shift into neutral and let it play out. If they bring it up, cool. If not, I'm not pushing it. | L2: 3 | M2: 4 | N2: 0 | O2: 0 | P2: 0 | Q2: Icebox | R2: 1 | U2: 0 | V2: masc:1.8;fem:-1.6 | W2: 1.8 | X2: -1.6 | Y2: COMM_Avoidant | Z2: REG_Suppressor | AA2: LANG_Time | AB2: Vulnerability_Loop , Pursuer_Distancer | AC2: Vulnerability_Loop | AD2: Pursuer_Distancer | AE2: 11 | AF2: emotional disengage | AG2: passive drifter | AH2: 0 | AI2: yes | AJ2: no | AK2: yes | AL2: yes | AP2: v3_2026-03-19
A3: Q01_B | B3: 1 | C3: 1 | D3: Core | E3: 1 | F3: CommunicationHealth | G3: EmotionalNeeds | I3: B | J3: B | K3: I start rereading everything. The tone in a text. A pause that felt a little too long. I like turning it into a puzzle to solve. | L3: 6 | M3: 7 | N3: 4 | O3: 6 | P3: 4 | Q3: Analyzer | R3: 2 | U3: 0 | V3: masc:1.4;fem:0.1 | W3: 1.4 | X3: 0.1 | Y3: COMM_Logical | Z3: REG_SelfSoother | AA3: LANG_Service | AB3: Trust_Tension | AC3: Trust_Tension | AE3: 6 | AF3: overanalysis | AG3: hyper-vigilant decoder | AH3: 0 | AI3: yes | AJ3: no | AK3: yes | AL3: yes | AP3: v3_2026-03-19
A4: Q01_C | B4: 1 | C4: 1 | D4: Core | E4: 1 | F4: CommunicationHealth | G4: EmotionalNeeds | I4: C | J4: C | K4: I'll bring something up, but I usually wrap it in a joke or a side comment. I'd rather ease into it than make it feel too serious. | L4: 7 | M4: 8 | N4: 6 | O4: 8 | P4: 8 | Q4: Translator | R4: 3 | U4: 0 | V4: masc:-0.1;fem:1.6 | W4: -0.1 | X4: 1.6 | Y4: COMM_Indirect | Z4: REG_CoRegulator | AA4: LANG_Words | AE4: 0 | AF4: soft entry communication | AG4: light approach | AH4: 0 | AI4: no | AJ4: no | AK4: yes | AL4: yes | AP4: v3_2026-03-19
A5: Q01_D | B5: 1 | C5: 1 | D5: Core | E5: 1 | F5: CommunicationHealth | G5: EmotionalNeeds | I5: D | J5: D | K5: I usually wait. Not to avoid it, just to feel it out first. I've learned not everything needs a reaction, but if it lingers, I'll say something. | L5: 8 | M5: 8 | N5: 8 | O5: 8 | P5: 6 | Q5: Survivor | R5: 8 | U5: 0 | V5: masc:0.3;fem:1.3 | W5: 0.3 | X5: 1.3 | Y5: COMM_Emotional | Z5: REG_SelfSoother | AA5: LANG_Service | AE5: 0 | AF5: measured patience | AG5: cautious feeler | AH5: 0.6 | AI5: no | AJ5: no | AK5: yes | AL5: yes | AP5: v3_2026-03-19
A6: Q01_E | B6: 1 | C6: 1 | D6: Core | E6: 1 | F6: CommunicationHealth | G6: EmotionalNeeds | I6: E | J6: E | K6: I don't do weird energy. I'm not unkind, but I also don't pretend. If something's off, I'm not sitting in it quietly. | L6: 9 | M6: 9 | N6: 10 | O6: 10 | P6: 10 | Q6: Regulated Grown-Up | R6: 9 | U6: 0 | V6: masc:1.1;fem:0.9 | W6: 1.1 | X6: 0.9 | Y6: COMM_Direct | Z6: REG_CoRegulator | AA6: LANG_Words | AE6: 0 | AF6: direct boundary setting | AG6: clear communicator | AH6: 0 | AI6: no | AJ6: no | AK6: yes | AL6: yes | AP6: v3_2026-03-19
A7: Q02_A | B7: 2 | C7: 2 | D7: Core | E7: 1 | F7: CommunicationHealth | G7: EmotionalNeeds | H7: You bring up something that bothered you. They brush it off or make a joke. What's your honest reaction? | I7: A | J7: A | K7: Not surprised. I usually go quieter after that. I've seen this play out before, no point chasing clarity where it's not offered. | L7: 5 | M7: 6 | N7: 0 | O7: 0 | P7: 0 | Q7: Quiet Exit | R7: 4 | U7: 0 | V7: masc:1.4;fem:-1.3 | W7: 1.4 | X7: -1.3 | Y7: COMM_Avoidant | Z7: REG_Suppressor | AA7: LANG_Time | AB7: Vulnerability_Loop , Pursuer_Distancer | AC7: Vulnerability_Loop | AD7: Pursuer_Distancer | AE7: 11 | AF7: withdrawal after dismissal | AG7: silent step-back | AH7: 0.8 | AI7: yes | AJ7: no | AK7: yes | AL7: yes | AP7: v3_2026-03-19
A8: Q02_B | B8: 2 | C8: 2 | D8: Core | E8: 1 | F8: CommunicationHealth | G8: EmotionalNeeds | I8: B | J8: B | K8: I'll play along, but it definitely changes how I see them. I keep score, even if they never know it. | L8: 4 | M8: 5 | N8: 0 | O8: 0 | P8: 0 | Q8: Performer | R8: 7 | U8: 0 | V8: masc:0.3;fem:0.5 | W8: 0.3 | X8: 0.5 | Y8: COMM_Indirect | Z8: REG_Distractor | AA8: LANG_Gifts | AB8: Control_Avoidance , Scorekeeping_Echo | AC8: Control_Avoidance | AD8: Scorekeeping_Echo | AE8: 14 | AF8: private resentment | AG8: image-based keeper | AH8: 1.2 | AI8: yes | AJ8: no | AK8: yes | AL8: yes | AP8: v3_2026-03-19
A9: Q02_C | B9: 2 | C9: 2 | D9: Core | E9: 1 | F9: CommunicationHealth | G9: EmotionalNeeds | I9: C | J9: C | K9: I bring it up again, but this time they can probably hear the shift in my tone. I'm not trying to argue, I just need them to actually hear me. | L9: 8 | M9: 8 | N9: 8 | O9: 8 | P9: 8 | Q9: Fixer | R9: 5 | U9: 0 | V9: masc:-0.4;fem:2.0 | W9: -0.4 | X9: 2 | Y9: COMM_Emotional | Z9: REG_CoRegulator | AA9: LANG_Service | AE9: 0 | AF9: persistence for resolution | AG9: consistent communicator | AH9: 0 | AI9: no | AJ9: no | AK9: yes | AL9: yes | AP9: v3_2026-03-19
A10: Q02_D | B10: 2 | C10: 2 | D10: Core | E10: 1 | F10: CommunicationHealth | G10: EmotionalNeeds | I10: D | J10: D | K10: I laugh too, but it sticks with me. Hours later I'm still replaying what I said, wondering if I should've just kept quiet. | L10: 5 | M10: 6 | N10: 2 | O10: 4 | P10: 2 | Q10: Phantom Seeker | R10: 10 | U10: 0 | V10: masc:-0.2;fem:1.5 | W10: -0.2 | X10: 1.5 | Y10: COMM_Emotional | Z10: REG_SelfSoother | AA10: LANG_Touch | AB10: Conflict_Flip | AC10: Conflict_Flip | AE10: 4 | AF10: quiet rumination | AG10: soft stewer | AH10: 0 | AI10: yes | AJ10: no | AK10: yes | AL10: yes | AP10: v3_2026-03-19
A11: Q02_E | B11: 2 | C11: 2 | D11: Core | E11: 1 | F11: CommunicationHealth | G11: EmotionalNeeds | I11: E | J11: E | K11: I clock that fast. If I opened up and they shrugged it off, I don't ask again. I don't mind being the bad guy if it means protecting my peace. | L11: 9 | M11: 9 | N11: 10 | O11: 10 | P11: 10 | Q11: Regulated Grown-Up | R11: 9 | U11: 0 | V11: masc:1.1;fem:0.9 | W11: 1.1 | X11: 0.9 | Y11: COMM_Direct | Z11: REG_CoRegulator | AA11: LANG_Words | AE11: 0 | AF11: fast boundary recognition | AG11: peace protector | AH11: 0 | AI11: no | AJ11: no | AK11: yes | AL11: yes | AP11: v3_2026-03-19
A12: Q03_A | B12: 3 | C12: 3 | D12: Core | E12: 1 | F12: CommunicationHealth | G12: EmotionalNeeds | H12: You start catching feelings and realizing you actually like this person. How does your energy shift? | I12: A | J12: A | K12: I pull back a little. Not to play games, I just need space to check if I'm seeing it clearly before I lean in. | L12: 6 | M12: 7 | N12: 2 | O12: 2 | P12: 0 | Q12: Icebox | R12: 1 | U12: 0 | V12: masc:1.8;fem:-1.6 | W12: 1.8 | X12: -1.6 | Y12: COMM_Avoidant | Z12: REG_Suppressor | AA12: LANG_Time | AE12: 0 | AF12: cautious distance | AG12: safety checker | AH12: 0.5 | AI12: no | AJ12: no | AK12: yes | AL12: yes | AP12: v3_2026-03-19
A13: Q03_B | B13: 3 | C13: 3 | D13: Core | E13: 1 | F13: CommunicationHealth | G13: EmotionalNeeds | I13: B | J13: B | K13: I start imagining what it could be. I try not to get ahead of myself, I just like feeling what it can be. | L13: 7 | M13: 8 | N13: 4 | O13: 6 | P13: 4 | Q13: Romantic Idealist | R13: 6 | U13: 0 | V13: masc:-0.4;fem:1.5 | W13: -0.4 | X13: 1.5 | Y13: COMM_Emotional | Z13: REG_Distractor | AA13: LANG_Gifts | AB13: Humor_Shield , Affection_Mismatch | AC13: Humor_Shield | AD13: Affection_Mismatch | AE13: 7 | AF13: guarded playfulness | AG13: safe tester | AH13: 0.2 | AI13: yes | AJ13: no | AK13: yes | AL13: yes | AP13: v3_2026-03-19
A14: Q03_C | B14: 3 | C14: 3 | D14: Core | E14: 1 | F14: CommunicationHealth | G14: EmotionalNeeds | I14: C | J14: C | K14: I don't say much, but I start showing up more, checking in, remembering little things. That's usually how I start showing my interest. | L14: 8 | M14: 9 | N14: 8 | O14: 8 | P14: 8 | Q14: Analyzer | R14: 2 | U14: 0 | V14: masc:1.4;fem:0.1 | W14: 1.4 | X14: 0.1 | Y14: COMM_Logical | Z14: REG_SelfSoother | AA14: LANG_Service | AE14: 0 | AF14: steady investment | AG14: quiet prover | AH14: 0 | AI14: no | AJ14: no | AK14: yes | AL14: yes | AP14: v3_2026-03-19
A15: Q03_D | B15: 3 | C15: 3 | D15: Core | E15: 1 | F15: CommunicationHealth | G15: EmotionalNeeds | I15: D | J15: D | K15: I want them to like me back, but I need to know it's safe first. So I keep it light while I wait on their actions. | L15: 6 | M15: 6 | N15: 4 | O15: 2 | P15: 2 | Q15: Phantom Seeker | R15: 10 | U15: 0 | V15: masc:-0.2;fem:1.5 | W15: -0.2 | X15: 1.5 | Y15: COMM_Emotional | Z15: REG_SelfSoother | AA15: LANG_Touch | AB15: Humor_Shield , Affection_Mismatch | AC15: Humor_Shield | AD15: Affection_Mismatch | AE15: 7 | AF15: guarded playfulness | AG15: safe tester | AH15: 0 | AI15: yes | AJ15: no | AK15: yes | AL15: yes | AP15: v3_2026-03-19
A16: Q03_E | B16: 3 | C16: 3 | D16: Core | E16: 1 | F16: CommunicationHealth | G16: EmotionalNeeds | I16: E | J16: E | K16: If I like someone, yeah, it shows. But I've learned not to lean too far until I know they're showing up too. I'm not trying to guess where I stand. | L16: 9 | M16: 9 | N16: 10 | O16: 10 | P16: 10 | Q16: Regulated Grown-Up | R16: 9 | U16: 0 | V16: masc:1.1;fem:0.9 | W16: 1.1 | X16: 0.9 | Y16: COMM_Direct | Z16: REG_CoRegulator | AA16: LANG_Words | AE16: 0 | AF16: balanced openness | AG16: readiness matcher | AH16: 0.2 | AI16: no | AJ16: no | AK16: yes | AL16: yes | AP16: v3_2026-03-19
A17: Q04_A | B17: 4 | C17: 4 | D17: Core | E17: 1 | F17: CommunicationHealth | G17: EmotionalNeeds | H17: You're starting to notice some red flags. Nothing explosive, just little things that don't sit right. What do you do with that feeling? | I17: A | J17: A | K17: I keep watching. I've learned not to bring things up too early. People need time to reveal themselves. | L17: 7 | M17: 8 | N17: 6 | O17: 6 | P17: 6 | Q17: Analyzer | R17: 2 | U17: 0 | V17: masc:1.4;fem:0.1 | W17: 1.4 | X17: 0.1 | Y17: COMM_Logical | Z17: REG_SelfSoother | AA17: LANG_Service | AE17: 0 | AF17: silent observation | AG17: patient tracker | AH17: 1.2 | AI17: no | AJ17: no | AK17: yes | AL17: yes | AP17: v3_2026-03-19
A18: Q04_B | B18: 4 | C18: 4 | D18: Core | E18: 1 | F18: CommunicationHealth | G18: EmotionalNeeds | I18: B | J18: B | K18: I ignore it at first. I don't want to ruin a good thing by overthinking. Sometimes I just want it to stay good for a little while. | L18: 5 | M18: 6 | N18: 2 | O18: 2 | P18: 0 | Q18: Romantic Idealist | R18: 6 | U18: 0 | V18: masc:-0.4;fem:1.5 | W18: -0.4 | X18: 1.5 | Y18: COMM_Emotional | Z18: REG_Distractor | AA18: LANG_Gifts | AB18: Commitment_Ambiguity | AC18: Commitment_Ambiguity | AE18: 5 | AF18: optimism over caution | AG18: avoidant hope | AH18: 0.6 | AI18: yes | AJ18: no | AK18: yes | AL18: yes | AP18: v3_2026-03-19
A19: Q04_C | B19: 4 | C19: 4 | D19: Core | E19: 1 | F19: CommunicationHealth | G19: EmotionalNeeds | I19: C | J19: C | K19: I call it out. I just say what I see. I'd rather know now than waste time. | L19: 10 | M19: 10 | N19: 10 | O19: 10 | P19: 10 | Q19: Regulated Grown-Up | R19: 9 | U19: 0 | V19: masc:1.1;fem:0.9 | W19: 1.1 | X19: 0.9 | Y19: COMM_Direct | Z19: REG_CoRegulator | AA19: LANG_Words | AE19: 0 | AF19: early clarity | AG19: straight talker | AH19: 0 | AI19: no | AJ19: no | AK19: yes | AL19: yes | AP19: v3_2026-03-19
A20: Q04_D | B20: 4 | C20: 4 | D20: Core | E20: 1 | F20: CommunicationHealth | G20: EmotionalNeeds | I20: D | J20: D | K20: I tell myself I'm just being too picky or expecting too much. So I wait. I just stop texting first and start holding back. | L20: 4 | M20: 5 | N20: 0 | O20: 2 | P20: 0 | Q20: Phantom Seeker | R20: 10 | U20: 0 | V20: masc:-0.2;fem:1.5 | W20: -0.2 | X20: 1.5 | Y20: COMM_Emotional | Z20: REG_SelfSoother | AA20: LANG_Touch | AB20: Commitment_Ambiguity | AC20: Commitment_Ambiguity | AE20: 5 | AF20: self-doubt delay | AG20: pullback protector | AH20: 0.6 | AI20: yes | AJ20: no | AK20: yes | AL20: yes | AP20: v3_2026-03-19
A21: Q04_E | B21: 4 | C21: 4 | D21: Core | E21: 1 | F21: CommunicationHealth | G21: EmotionalNeeds | I21: E | J21: E | K21: I've learned not to announce when I'm done, I just leave when I'm sure. I downplay it out loud, but mentally I start planning my exit. | L21: 8 | M21: 8 | N21: 4 | O21: 4 | P21: 0 | Q21: Quiet Exit | R21: 4 | U21: 0 | V21: masc:1.4;fem:-1.3 | W21: 1.4 | X21: -1.3 | Y21: COMM_Avoidant | Z21: REG_Suppressor | AA21: LANG_Time | AE21: 0 | AF21: silent exit plan | AG21: strategic withdrawer | AH21: 1.2 | AI21: no | AJ21: no | AK21: yes | AL21: yes | AP21: v3_2026-03-19
A22: Q05_A | B22: 5 | C22: 5 | D22: Core | E22: 1 | F22: CommunicationHealth | G22: EmotionalNeeds | H22: You open up about something personal. They listen, but they don't really respond or say much. How do you take that? | I22: A | J22: A | K22: I don't expect much from people emotionally. I just log it as "noted" and move on. No point getting deep with someone who doesn't meet you there. | L22: 4 | M22: 5 | N22: 0 | O22: 0 | P22: 0 | Q22: Icebox | R22: 1 | U22: 0 | V22: masc:1.8;fem:-1.6 | W22: 1.8 | X22: -1.6 | Y22: COMM_Avoidant | Z22: REG_Suppressor | AA22: LANG_Time | AB22: Scorekeeping_Echo , Vulnerability_Loop | AC22: Scorekeeping_Echo | AD22: Vulnerability_Loop | AE22: 13 | AF22: low expectation logging | AG22: cool detacher | AH22: 0.6 | AI22: yes | AJ22: no | AK22: yes | AL22: yes | AP22: v3_2026-03-19
A23: Q05_B | B23: 5 | C23: 5 | D23: Core | E23: 1 | F23: CommunicationHealth | G23: EmotionalNeeds | I23: B | J23: B | K23: I brush it off, but I don't forget it. Stuff like that reminds me who's safe and who just wants the easy version of me. | L23: 6 | M23: 7 | N23: 4 | O23: 6 | P23: 6 | Q23: Survivor | R23: 8 | U23: 0 | V23: masc:0.3;fem:1.3 | W23: 0.3 | X23: 1.3 | Y23: COMM_Emotional | Z23: REG_SelfSoother | AA23: LANG_Service | AE23: 0 | AF23: guarded memory | AG23: loyalty filter | AH23: 0 | AI23: no | AJ23: no | AK23: yes | AL23: yes | AP23: v3_2026-03-19
A24: Q05_C | B24: 5 | C24: 5 | D24: Core | E24: 1 | F24: CommunicationHealth | G24: EmotionalNeeds | I24: C | J24: C | K24: I try to explain again, maybe they didn't get it. And if they still don't? I stop showing that side to someone who doesn't see me. | L24: 8 | M24: 9 | N24: 8 | O24: 10 | P24: 8 | Q24: Fixer | R24: 5 | U24: 0 | V24: masc:-0.4;fem:2.0 | W24: -0.4 | X24: 2 | Y24: COMM_Emotional | Z24: REG_CoRegulator | AA24: LANG_Service | AE24: 0 | AF24: repair attempt | AG24: persistent helper | AH24: 0 | AI24: no | AJ24: no | AK24: yes | AL24: yes | AP24: v3_2026-03-19
A25: Q05_D | B25: 5 | C25: 5 | D25: Core | E25: 1 | F25: CommunicationHealth | G25: EmotionalNeeds | I25: D | J25: D | K25: I keep it smooth, but I notice the shift. Makes me rethink what I share next time, it's easier to just stay surface when people don't respond. | L25: 5 | M25: 6 | N25: 0 | O25: 2 | P25: 0 | Q25: Performer | R25: 7 | U25: 0 | V25: masc:0.3;fem:0.5 | W25: 0.3 | X25: 0.5 | Y25: COMM_Indirect | Z25: REG_Distractor | AA25: LANG_Gifts | AB25: Public_Private_Split , Conflict_Flip | AC25: Public_Private_Split | AD25: Conflict_Flip | AE25: 8 | AF25: image-based withdrawal | AG25: surface masker | AH25: 1.2 | AI25: yes | AJ25: no | AK25: yes | AL25: yes | AP25: v3_2026-03-19
A26: Q05_E | B26: 5 | C26: 5 | D26: Core | E26: 1 | F26: CommunicationHealth | G26: EmotionalNeeds | I26: E | J26: E | K26: Silence says a lot. I take note. If they care, it'll show later, if not, I don't open that part of me again. | L26: 9 | M26: 9 | N26: 10 | O26: 10 | P26: 10 | Q26: Regulated Grown-Up | R26: 9 | U26: 0 | V26: masc:1.1;fem:0.9 | W26: 1.1 | X26: 0.9 | Y26: COMM_Direct | Z26: REG_CoRegulator | AA26: LANG_Words | AE26: 0 | AF26: high awareness | AG26: calm sentinel | AH26: 0 | AI26: no | AJ26: no | AK26: yes | AL26: yes | AP26: v3_2026-03-19
A27: Q06_A | B27: 6 | C27: 6 | D27: Core | E27: 1 | F27: CommunicationHealth | G27: EmotionalNeeds | H27: Question 6: One day they're into you, then distant the next. How do you handle the mixed signals? | I27: A | J27: A | K27: If you're hot and cold, I'm room temperature and gone. I'm not here to decode moods. | L27: 9 | M27: 9 | N27: 10 | O27: 10 | P27: 10 | Q27: Regulated Grown-Up | R27: 9 | U27: 0 | V27: masc:1.1;fem:0.9 | W27: 1.1 | X27: 0.9 | Y27: COMM_Direct | Z27: REG_CoRegulator | AA27: LANG_Words | AE27: 0 | AF27: blunt detachment | AG27: immediate cutoff | AH27: 1.2 | AI27: no | AJ27: no | AK27: yes | AL27: yes | AP27: v3_2026-03-19
A28: Q06_B | B28: 6 | C28: 6 | D28: Core | E28: 1 | F28: CommunicationHealth | G28: EmotionalNeeds | I28: B | J28: B | K28: I recheck our last texts. Then I reread mine. Then I wonder if I should've said less, or more. I don't bring it up, but it definitely rewires how I respond. | L28: 5 | M28: 6 | N28: 4 | O28: 4 | P28: 2 | Q28: Analyzer | R28: 2 | U28: 0 | V28: masc:1.4;fem:0.1 | W28: 1.4 | X28: 0.1 | Y28: COMM_Logical | Z28: REG_SelfSoother | AA28: LANG_Service | AB28: Trust_Tension | AC28: Trust_Tension | AE28: 6 | AF28: emotional spiral | AG28: overanalyzer | AH28: 0 | AI28: yes | AJ28: no | AK28: yes | AL28: yes | AP28: v3_2026-03-19
A29: Q06_C | B29: 6 | C29: 6 | D29: Core | E29: 1 | F29: CommunicationHealth | G29: EmotionalNeeds | I29: C | J29: C | K29: I back off. They'll either notice or they won't. I'm not chasing people who don't know what they want. | L29: 4 | M29: 5 | N29: 0 | O29: 0 | P29: 0 | Q29: Icebox | R29: 1 | U29: 0 | V29: masc:1.8;fem:-1.6 | W29: 1.8 | X29: -1.6 | Y29: COMM_Avoidant | Z29: REG_Suppressor | AA29: LANG_Time | AB29: Vulnerability_Loop | AC29: Vulnerability_Loop | AE29: 5 | AF29: quiet burn | AG29: disengaged pullback | AH29: 0.6 | AI29: yes | AJ29: no | AK29: yes | AL29: yes | AP29: v3_2026-03-19
A30: Q06_D | B30: 6 | C30: 6 | D30: Core | E30: 1 | F30: CommunicationHealth | G30: EmotionalNeeds | I30: D | J30: D | K30: I stop bringing things up. If they don't want me, I'm not going to beg to be understood. I've played that game before. | L30: 6 | M30: 7 | N30: 4 | O30: 4 | P30: 4 | Q30: Fixer | R30: 5 | U30: 0 | V30: masc:-0.4;fem:2.0 | W30: -0.4 | X30: 2 | Y30: COMM_Emotional | Z30: REG_CoRegulator | AA30: LANG_Service | AB30: Affection_Mismatch , Independence_Collision | AC30: Affection_Mismatch | AD30: Independence_Collision | AE30: 9 | AF30: resigned caregiver | AG30: silent surrender | AH30: 1.2 | AI30: yes | AJ30: no | AK30: yes | AL30: yes | AP30: v3_2026-03-19
A31: Q06_E | B31: 6 | C31: 6 | D31: Core | E31: 1 | F31: CommunicationHealth | G31: EmotionalNeeds | I31: E | J31: E | K31: I tell myself it's probably just stress or a bad week. I don't want to give up too early, but it's hard not to notice when it shifts. | L31: 7 | M31: 8 | N31: 6 | O31: 6 | P31: 4 | Q31: Romantic Idealist | R31: 6 | U31: 0 | V31: masc:-0.4;fem:1.5 | W31: -0.4 | X31: 1.5 | Y31: COMM_Emotional | Z31: REG_Distractor | AA31: LANG_Gifts | AE31: 0 | AF31: tired hope | AG31: cautious optimist | AH31: 0 | AI31: no | AJ31: no | AK31: yes | AL31: yes | AP31: v3_2026-03-19
A32: Q07_A | B32: 7 | C32: 7 | D32: Core | E32: 1 | F32: CommunicationHealth | G32: EmotionalNeeds | H32: Question 7: You're deep in conversation and they suddenly shut down or go cold. What's your move? | I32: A | J32: A | K32: I pause. I've learned not everything's about me. If they want to talk, they will. If not, I don't chase silence. | L32: 8 | M32: 8 | N32: 4 | O32: 4 | P32: 0 | Q32: Icebox | R32: 1 | U32: 0 | V32: masc:1.8;fem:-1.6 | W32: 1.8 | X32: -1.6 | Y32: COMM_Avoidant | Z32: REG_Suppressor | AA32: LANG_Time | AE32: 0 | AF32: calm detachment | AG32: patient withdrawer | AH32: 0.8 | AI32: no | AJ32: no | AK32: yes | AL32: yes | AP32: v3_2026-03-19
A33: Q07_B | B33: 7 | C33: 7 | D33: Core | E33: 1 | F33: CommunicationHealth | G33: EmotionalNeeds | I33: B | J33: B | K33: I immediately think I said something wrong. I start scanning every word trying to figure out what triggered it. | L33: 5 | M33: 6 | N33: 4 | O33: 4 | P33: 2 | Q33: Analyzer | R33: 2 | U33: 0 | V33: masc:1.4;fem:0.1 | W33: 1.4 | X33: 0.1 | Y33: COMM_Logical | Z33: REG_SelfSoother | AA33: LANG_Service | AB33: Vulnerability_Loop | AC33: Vulnerability_Loop | AE33: 5 | AF33: inner spiral | AG33: self-blamer | AH33: 0 | AI33: yes | AJ33: no | AK33: yes | AL33: yes | AP33: v3_2026-03-19
A34: Q07_C | B34: 7 | C34: 7 | D34: Core | E34: 1 | F34: CommunicationHealth | G34: EmotionalNeeds | I34: C | J34: C | K34: I'll ask once. If it's brushed off or ignored, I shift. I'm not the type to sit in someone else's silence for long. | L34: 9 | M34: 9 | N34: 10 | O34: 10 | P34: 10 | Q34: Regulated Grown-Up | R34: 9 | U34: 0 | V34: masc:1.1;fem:0.9 | W34: 1.1 | X34: 0.9 | Y34: COMM_Direct | Z34: REG_CoRegulator | AA34: LANG_Words | AE34: 0 | AF34: direct with boundaries | AG34: firm line-setter | AH34: 0 | AI34: no | AJ34: no | AK34: yes | AL34: yes | AP34: v3_2026-03-19
A35: Q07_D | B35: 7 | C35: 7 | D35: Core | E35: 1 | F35: CommunicationHealth | G35: EmotionalNeeds | I35: D | J35: D | K35: I try to keep the mood up, shift the subject, make it feel less tense, even if I'm freaking out a little inside. | L35: 6 | M35: 7 | N35: 4 | O35: 4 | P35: 2 | Q35: Performer | R35: 7 | U35: 0 | V35: masc:0.3;fem:0.5 | W35: 0.3 | X35: 0.5 | Y35: COMM_Indirect | Z35: REG_Distractor | AA35: LANG_Gifts | AB35: Vulnerability_Loop | AC35: Vulnerability_Loop | AE35: 5 | AF35: smooth cover-up | AG35: tension diffuser | AH35: 0 | AI35: yes | AJ35: no | AK35: yes | AL35: yes | AP35: v3_2026-03-19
A36: Q07_E | B36: 7 | C36: 7 | D36: Core | E36: 1 | F36: CommunicationHealth | G36: EmotionalNeeds | I36: E | J36: E | K36: I feel it, but I don't say anything. I stay present, hoping they'll come back to me on their own. | L36: 6 | M36: 6 | N36: 4 | O36: 4 | P36: 4 | Q36: Translator | R36: 3 | U36: 0 | V36: masc:-0.1;fem:1.6 | W36: -0.1 | X36: 1.6 | Y36: COMM_Indirect | Z36: REG_CoRegulator | AA36: LANG_Words | AB36: Vulnerability_Loop | AC36: Vulnerability_Loop | AE36: 5 | AF36: gentle waiter | AG36: silent holder | AH36: 0.6 | AI36: yes | AJ36: no | AK36: yes | AL36: yes | AP36: v3_2026-03-19
A37: Q08_A | B37: 8 | C37: 8 | D37: Core | E37: 1 | F37: CommunicationHealth | G37: EmotionalNeeds | H37: Question 8: You feel them pulling away. They haven't said it, but the shift is obvious. What runs through your head first? | I37: A | J37: A | K37: Here we go again. I already know how this plays out. I stop trying the second I feel myself caring more than they do. | L37: 5 | M37: 5 | N37: 4 | O37: 2 | P37: 2 | Q37: Survivor | R37: 8 | U37: 0 | V37: masc:0.3;fem:1.3 | W37: 0.3 | X37: 1.3 | Y37: COMM_Emotional | Z37: REG_SelfSoother | AA37: LANG_Service | AB37: Vulnerability_Loop | AC37: Vulnerability_Loop | AE37: 5 | AF37: pain-calibrated exit | AG37: early withdrawer | AH37: 0.6 | AI37: yes | AJ37: no | AK37: yes | AL37: yes | AP37: v3_2026-03-19
A38: Q08_B | B38: 8 | C38: 8 | D38: Core | E38: 1 | F38: CommunicationHealth | G38: EmotionalNeeds | I38: B | J38: B | K38: It's subtle, but I clock everything. Less emojis. Slower replies. Something's off, I just haven't figured out what yet. | L38: 7 | M38: 8 | N38: 6 | O38: 6 | P38: 6 | Q38: Analyzer | R38: 2 | U38: 0 | V38: masc:1.4;fem:0.1 | W38: 1.4 | X38: 0.1 | Y38: COMM_Logical | Z38: REG_SelfSoother | AA38: LANG_Service | AE38: 0 | AF38: pattern tracker | AG38: micro-signal reader | AH38: 0.6 | AI38: no | AJ38: no | AK38: yes | AL38: yes | AP38: v3_2026-03-19
A39: Q08_C | B39: 8 | C39: 8 | D39: Core | E39: 1 | F39: CommunicationHealth | G39: EmotionalNeeds | I39: C | J39: C | K39: I don't ask. I just start detaching. If you're fading, I'm not chasing. I've done that before, and I don't owe anyone a meltdown. | L39: 5 | M39: 6 | N39: 0 | O39: 2 | P39: 0 | Q39: Quiet Exit | R39: 4 | U39: 0 | V39: masc:1.4;fem:-1.3 | W39: 1.4 | X39: -1.3 | Y39: COMM_Avoidant | Z39: REG_Suppressor | AA39: LANG_Time | AB39: Vulnerability_Loop | AC39: Vulnerability_Loop | AE39: 5 | AF39: soft boundary | AG39: quiet exit | AH39: 0.2 | AI39: yes | AJ39: no | AK39: yes | AL39: yes | AP39: v3_2026-03-19
A40: Q08_D | B40: 8 | C40: 8 | D40: Core | E40: 1 | F40: CommunicationHealth | G40: EmotionalNeeds | I40: D | J40: D | K40: Maybe they just need space. I try not to assume the worst... but yeah, it's hard not to take it personal. | L40: 7 | M40: 8 | N40: 6 | O40: 6 | P40: 4 | Q40: Romantic Idealist | R40: 6 | U40: 0 | V40: masc:-0.4;fem:1.5 | W40: -0.4 | X40: 1.5 | Y40: COMM_Emotional | Z40: REG_Distractor | AA40: LANG_Gifts | AE40: 0 | AF40: fragile optimism | AG40: tentative hope | AH40: 0 | AI40: no | AJ40: no | AK40: yes | AL40: yes | AP40: v3_2026-03-19
...

Sheet QuestionWeights_v4
A1: q | B1: phase | C1: question_weight
A2: 1 | B2: Core | C2: 1
A3: 2 | B3: Core | C3: 1
A4: 3 | B4: Core | C4: 1
A5: 4 | B5: Core | C5: 1
A6: 5 | B6: Core | C6: 1
A7: 6 | B7: Core | C7: 1
A8: 7 | B8: Core | C8: 1
A9: 8 | B9: Core | C9: 1
A10: 9 | B10: Core | C10: 1.05
A11: 10 | B11: Core | C11: 1.05
A12: 11 | B12: Core | C12: 1.05
A13: 12 | B13: Core | C13: 1.05
... A61: 60 | B61: Shadow | C61: 1.35

Sheet ArchetypeLookup_v4
A1: pair_key | B1: score_2_9
A2: ANALYZER|ANALYZER | B2: 7
A3: ANALYZER|FIXER | B3: 6
A4: ANALYZER|ICEBOX | B4: 5
A5: ANALYZER|PHANTOM | B5: 4
A6: ANALYZER|QUIETEXIT | B6: 6
A7: ANALYZER|REGULATED | B7: 8
A8: ANALYZER|ROMANTIC | B8: 5
A9: ANALYZER|PERFORMER | B9: 4
A10: ANALYZER|SURVIVOR | B10: 6
A11: ANALYZER|TRANSLATOR | B11: 7
A12: FIXER|ANALYZER | B12: 6
A13: FIXER|FIXER | B13: 7
... A101: TRANSLATOR|TRANSLATOR | B101: 8

Sheet ShadowLookup_v4
A1: pair_key | B1: score_2_6
A2: MANIPULATOR_MANIPULATOR | B2: 3
A3: MANIPULATOR_STONEWALLER | B3: 2
A4: LOVEBOMBER_MANIPULATOR | B4: 2
A5: CHAMELEON_MANIPULATOR | B5: 2
A6: MANIPULATOR_SCOREKEEPER | B6: 2
A7: MANIPULATOR_SELFSABOTEUR | B7: 3
A8: MANIPULATOR_STONEWALLER | B8: 2
A9: STONEWALLER_STONEWALLER | B9: 4
A10: LOVEBOMBER_STONEWALLER | B10: 2
A11: CHAMELEON_STONEWALLER | B11: 4
A12: SCOREKEEPER_STONEWALLER | B12: 3
A13: SELFSABOTEUR_STONEWALLER | B13: 3
... A37: SELFSABOTEUR_SELFSABOTEUR | B37: 4

Sheet AstrologyLookup_v4
A1: pair_key | B1: score_1_10
A2: AR_M+AR_F | B2: 6
A3: AR_M+LI_F | B3: 7
A4: AR_M+TA_F | B4: 7
A5: AR_M+VI_F | B5: 6
A6: AR_M+SC_F | B6: 5
A7: AR_M+CA_F | B7: 4
A8: AR_M+GE_F | B8: 5
A9: AR_M+LE_F | B9: 8
A10: AR_M+CP_F | B10: 4
A11: AR_M+SG_F | B11: 6
A12: TA_M+TA_F | B12: 6
A13: AR_M+AQ_F | B13: 6
... A577: PI_F+CA_F | B577: 6

Sheet NumerologyLookup_v4
A1: pair_key | B1: score_1_10 | C1: weight_points
A2: 1+2 | B2: 6 | C2: 30
A3: 1+1 | B3: 7 | C3: 30
A4: 1+5 | B4: 9 | C4: 30
A5: 1+3 | B5: 6 | C5: 30
A6: 1+8 | B6: 6 | C6: 30
A7: 1+11 | B7: 6 | C7: 30
A8: 1+6 | B8: 6 | C8: 30
A9: 1+7 | B9: 8 | C9: 30
A10: 1+4 | B10: 6 | C10: 30
A11: 1+9 | B11: 8 | C11: 30
A12: 2+3 | B12: 6 | C12: 30
A13: 2+2 | B13: 7 | C13: 30
... A67: 9+22 | B67: 10 | C67: 30

Sheet CommLookup_v4
A1: pair_key | B1: score_1_10
A2: COMM_Avoidant+COMM_Direct | B2: 3
A3: COMM_Direct+COMM_Emotional | B3: 6
A4: COMM_Direct+COMM_Direct | B4: 8
A5: COMM_Avoidant+COMM_Emotional | B5: 5
A6: COMM_Avoidant+COMM_Avoidant | B6: 2
A7: COMM_Avoidant+COMM_Indirect | B7: 7
A8: COMM_Direct+COMM_Indirect | B8: 4
A9: COMM_Avoidant+COMM_Logical | B9: 6
A10: COMM_Direct+COMM_Logical | B10: 9
A11: COMM_Emotional+COMM_Emotional | B11: 7
A12: COMM_Emotional+COMM_Indirect | B12: 6
A13: COMM_Indirect+COMM_Logical | B13: 6
... A16: COMM_Indirect+COMM_Indirect | B16: 5

Sheet RegLookup_v4
A1: pair_key | B1: score_1_10
A2: REG_CoRegulator+REG_SelfSoother | B2: 10
A3: REG_Distractor+REG_SelfSoother | B3: 7
A4: REG_SelfSoother+REG_SelfSoother | B4: 8
A5: REG_Suppressor+REG_Suppressor | B5: 3
A6: REG_CoRegulator+REG_Distractor | B6: 6
A7: REG_Distractor+REG_Suppressor | B7: 4
A8: REG_CoRegulator+REG_CoRegulator | B8: 9
A9: REG_Distractor+REG_Distractor | B9: 7
A10: REG_SelfSoother+REG_Suppressor | B10: 6
A11: REG_CoRegulator+REG_Suppressor | B11: 5

Sheet LoveLookup_v4
A1: pair_key | B1: score_1_10
A2: LANG_Time+LANG_Touch | B2: 8
A3: LANG_Gifts+LANG_Words | B3: 6
A4: LANG_Time+LANG_Words | B4: 8
A5: LANG_Words+LANG_Words | B5: 9
A6: LANG_Gifts+LANG_Time | B6: 6
A7: LANG_Service+LANG_Time | B7: 9
A8: LANG_Touch+LANG_Words | B8: 7
A9: LANG_Gifts+LANG_Gifts | B9: 7
A10: LANG_Time+LANG_Time | B10: 10
A11: LANG_Service+LANG_Words | B11: 7
A12: LANG_Touch+LANG_Touch | B12: 9
A13: LANG_Gifts+LANG_Service | B13: 5
... A16: LANG_Service+LANG_Service | B16: 9

Sheet InteractionRules_v4
A1: rule_id | B1: source_type | C1: source_value | D1: target_type | E1: target_value | F1: pair_effect | G1: compatibility_modifier | H1: forecast_modifier | I1: source
A2: R1 | B2: archetype | C2: Analyzer | D2: shadow | E2: Stonewaller | F2: clarity pursuit meets withholding -> escalation | G2: -18 | H2: -12 | I2: Blueprint example
A3: R2 | B3: archetype | C3: Fixer | D3: archetype | E3: Survivor | F3: caretaker-protection dynamic; healing but imbalance risk | G3: 10 | H3: -4 | I3: Blueprint example
A4: R3 | B4: archetype | C4: Romantic Idealist | D4: archetype | E4: Performer | F4: spark + affirmation loop; fantasy amplification | G4: 12 | H4: -10 | I4: Blueprint example
A5: R4 | B5: archetype | C5: Translator | D5: archetype | E5: Regulated Grown-Up | F5: strong repair capacity + emotional translation | G5: 18 | H5: 12 | I5: Blueprint example
A6: R5 | F6: (add rules here) | G6: 0 | H6: 0 | I6: Editable

Sheet AstroSignMap_v4
A1: sun_sign | B1: abbr
A2: aries | B2: AR
A3: taurus | B3: TA
A4: gemini | B4: GE
A5: cancer | B5: CA
A6: leo | B6: LE
A7: virgo | B7: VI
A8: libra | B8: LI
A9: scorpio | B9: SC
A10: sagittarius | B10: SG
A11: capricorn | B11: CP
A12: aquarius | B12: AQ
A13: pisces | B13: PI

Sheet TestHarness_v4
A1: Test Harness (enter answer_id for each question)
A3: User A | F3: User B
A4: Gender (M/F) | B4: M | F4: Gender (M/F) | G4: F
A5: Sun sign (lowercase) | B5: aries | F5: Sun sign (lowercase) | G5: libra
A6: Life Path | B6: 1 | F6: Life Path | G6: 6
A9: q | B9: w_q | C9: dimension | D9: answer_id_A | E9: answer_id_B | F9: cA | G9: rA | H9: fA | I9: cpA | J9: cB | K9: rB | L9: fB | M9: cpB | N9: match | O9: quality | P9: pair_q | Q9: readinessContrA | R9: readinessContrB | S9: clusterA | T9: clusterB
A10: 1 | B10: =VLOOKUP(A10,QuestionWeights_v4!$A$2:$C$61,3,FALSE) | C10: =IFERROR(VLOOKUP(D10,AnswerBank_v5!$A$2:$AP$311,6,FALSE),"") | F10: =IFERROR(VLOOKUP(D10,AnswerBank_v5!$A$2:$AP$311,15,FALSE)/10,"") | G10: =IFERROR(VLOOKUP(D10,AnswerBank_v5!$A$2:$AP$311,14,FALSE)/10,"") | H10: =IFERROR(VLOOKUP(D10,AnswerBank_v5!$A$2:$AP$311,16,FALSE)/10,"") | I10: =IFERROR(VLOOKUP(D10,AnswerBank_v5!$A$2:$AP$311,31,FALSE),0) | J10: =IFERROR(VLOOKUP(E10,AnswerBank_v5!$A$2:$AP$311,15,FALSE)/10,"") | K10: =IFERROR(VLOOKUP(E10,AnswerBank_v5!$A$2:$AP$311,14,FALSE)/10,"") | L10: =IFERROR(VLOOKUP(E10,AnswerBank_v5!$A$2:$AP$311,16,FALSE)/10,"") | M10: =IFERROR(VLOOKUP(E10,AnswerBank_v5!$A$2:$AP$311,31,FALSE),0) | N10: =IF(OR(F10="",J10=""),"",1-ABS(F10-J10)) | O10: =IF(OR(G10="",K10="",H10="",L10=""),"",0.60+0.20*((G10+K10)/2)+0.20*((H10+L10)/2)) | P10: =IF(OR(B10="",N10="",O10=""),"",B10*N10*O10) | Q10: =IF(B10="", "", B10*(0.50*G10+0.20*H10+0.20*F10+0.10*(1-I10/25))) | R10: =IF(B10="", "", B10*(0.50*K10+0.20*L10+0.20*J10+0.10*(1-M10/25))) | S10: =IFERROR(VLOOKUP(D10,AnswerBank_v5!$A$2:$AP$311,29,FALSE),"") | T10: =IFERROR(VLOOKUP(E10,AnswerBank_v5!$A$2:$AP$311,29,FALSE),"")
A11: 2 | B11: =VLOOKUP(A11,QuestionWeights_v4!$A$2:$C$61,3,FALSE) | C11: =IFERROR(VLOOKUP(D11,AnswerBank_v5!$A$2:$AP$311,6,FALSE),"") | F11: =IFERROR(VLOOKUP(D11,AnswerBank_v5!$A$2:$AP$311,15,FALSE)/10,"") | G11: =IFERROR(VLOOKUP(D11,AnswerBank_v5!$A$2:$AP$311,14,FALSE)/10,"") | H11: =IFERROR(VLOOKUP(D11,AnswerBank_v5!$A$2:$AP$311,16,FALSE)/10,"") | I11: =IFERROR(VLOOKUP(D11,AnswerBank_v5!$A$2:$AP$311,31,FALSE),0) | J11: =IFERROR(VLOOKUP(E11,AnswerBank_v5!$A$2:$AP$311,15,FALSE)/10,"") | K11: =IFERROR(VLOOKUP(E11,AnswerBank_v5!$A$2:$AP$311,14,FALSE)/10,"") | L11: =IFERROR(VLOOKUP(E11,AnswerBank_v5!$A$2:$AP$311,16,FALSE)/10,"") | M11: =IFERROR(VLOOKUP(E11,AnswerBank_v5!$A$2:$AP$311,31,FALSE),0) | N11: =IF(OR(F11="",J11=""),"",1-ABS(F11-J11)) | O11: =IF(OR(G11="",K11="",H11="",L11=""),"",0.60+0.20*((G11+K11)/2)+0.20*((H11+L11)/2)) | P11: =IF(OR(B11="",N11="",O11=""),"",B11*N11*O11) | Q11: =IF(B11="", "", B11*(0.50*G11+0.20*H11+0.20*F11+0.10*(1-I11/25))) | R11: =IF(B11="", "", B11*(0.50*K11+0.20*L11+0.20*J11+0.10*(1-M11/25))) | S11: =IFERROR(VLOOKUP(D11,AnswerBank_v5!$A$2:$AP$311,29,FALSE),"") | T11: =IFERROR(VLOOKUP(E11,AnswerBank_v5!$A$2:$AP$311,29,FALSE),"")
A12: 3 | B12: =VLOOKUP(A12,QuestionWeights_v4!$A$2:$C$61,3,FALSE) | C12: =IFERROR(VLOOKUP(D12,AnswerBank_v5!$A$2:$AP$311,6,FALSE),"") | F12: =IFERROR(VLOOKUP(D12,AnswerBank_v5!$A$2:$AP$311,15,FALSE)/10,"") | G12: =IFERROR(VLOOKUP(D12,AnswerBank_v5!$A$2:$AP$311,14,FALSE)/10,"") | H12: =IFERROR(VLOOKUP(D12,AnswerBank_v5!$A$2:$AP$311,16,FALSE)/10,"") | I12: =IFERROR(VLOOKUP(D12,AnswerBank_v5!$A$2:$AP$311,31,FALSE),0) | J12: =IFERROR(VLOOKUP(E12,AnswerBank_v5!$A$2:$AP$311,15,FALSE)/10,"") | K12: =IFERROR(VLOOKUP(E12,AnswerBank_v5!$A$2:$AP$311,14,FALSE)/10,"") | L12: =IFERROR(VLOOKUP(E12,AnswerBank_v5!$A$2:$AP$311,16,FALSE)/10,"") | M12: =IFERROR(VLOOKUP(E12,AnswerBank_v5!$A$2:$AP$311,31,FALSE),0) | N12: =IF(OR(F12="",J12=""),"",1-ABS(F12-J12)) | O12: =IF(OR(G12="",K12="",H12="",L12=""),"",0.60+0.20*((G12+K12)/2)+0.20*((H12+L12)/2)) | P12: =IF(OR(B12="",N12="",O12=""),"",B12*N12*O12) | Q12: =IF(B12="", "", B12*(0.50*G12+0.20*H12+0.20*F12+0.10*(1-I12/25))) | R12: =IF(B12="", "", B12*(0.50*K12+0.20*L12+0.20*J12+0.10*(1-M12/25))) | S12: =IFERROR(VLOOKUP(D12,AnswerBank_v5!$A$2:$AP$311,29,FALSE),"") | T12: =IFERROR(VLOOKUP(E12,AnswerBank_v5!$A$2:$AP$311,29,FALSE),"")
A13: 4 | B13: =VLOOKUP(A13,QuestionWeights_v4!$A$2:$C$61,3,FALSE) | C13: =IFERROR(VLOOKUP(D13,AnswerBank_v5!$A$2:$AP$311,6,FALSE),"") | F13: =IFERROR(VLOOKUP(D13,AnswerBank_v5!$A$2:$AP$311,15,FALSE)/10,"") | G13: =IFERROR(VLOOKUP(D13,AnswerBank_v5!$A$2:$AP$311,14,FALSE)/10,"") | H13: =IFERROR(VLOOKUP(D13,AnswerBank_v5!$A$2:$AP$311,16,FALSE)/10,"") | I13: =IFERROR(VLOOKUP(D13,AnswerBank_v5!$A$2:$AP$311,31,FALSE),0) | J13: =IFERROR(VLOOKUP(E13,AnswerBank_v5!$A$2:$AP$311,15,FALSE)/10,"") | K13: =IFERROR(VLOOKUP(E13,AnswerBank_v5!$A$2:$AP$311,14,FALSE)/10,"") | L13: =IFERROR(VLOOKUP(E13,AnswerBank_v5!$A$2:$AP$311,16,FALSE)/10,"") | M13: =IFERROR(VLOOKUP(E13,AnswerBank_v5!$A$2:$AP$311,31,FALSE),0) | N13: =IF(OR(F13="",J13=""),"",1-ABS(F13-J13)) | O13: =IF(OR(G13="",K13="",H13="",L13=""),"",0.60+0.20*((G13+K13)/2)+0.20*((H13+L13)/2)) | P13: =IF(OR(B13="",N13="",O13=""),"",B13*N13*O13) | Q13: =IF(B13="", "", B13*(0.50*G13+0.20*H13+0.20*F13+0.10*(1-I13/25))) | R13: =IF(B13="", "", B13*(0.50*K13+0.20*L13+0.20*J13+0.10*(1-M13/25))) | S13: =IFERROR(VLOOKUP(D13,AnswerBank_v5!$A$2:$AP$311,29,FALSE),"") | T13: =IFERROR(VLOOKUP(E13,AnswerBank_v5!$A$2:$AP$311,29,FALSE),"")
A14: 5 | B14: =VLOOKUP(A14,QuestionWeights_v4!$A$2:$C$61,3,FALSE) | C14: =IFERROR(VLOOKUP(D14,AnswerBank_v5!$A$2:$AP$311,6,FALSE),"") | F14: =IFERROR(VLOOKUP(D14,AnswerBank_v5!$A$2:$AP$311,15,FALSE)/10,"") | G14: =IFERROR(VLOOKUP(D14,AnswerBank_v5!$A$2:$AP$311,14,FALSE)/10,"") | H14: =IFERROR(VLOOKUP(D14,AnswerBank_v5!$A$2:$AP$311,16,FALSE)/10,"") | I14: =IFERROR(VLOOKUP(D14,AnswerBank_v5!$A$2:$AP$311,31,FALSE),0) | J14: =IFERROR(VLOOKUP(E14,AnswerBank_v5!$A$2:$AP$311,15,FALSE)/10,"") | K14: =IFERROR(VLOOKUP(E14,AnswerBank_v5!$A$2:$AP$311,14,FALSE)/10,"") | L14: =IFERROR(VLOOKUP(E14,AnswerBank_v5!$A$2:$AP$311,16,FALSE)/10,"") | M14: =IFERROR(VLOOKUP(E14,AnswerBank_v5!$A$2:$AP$311,31,FALSE),0) | N14: =IF(OR(F14="",J14=""),"",1-ABS(F14-J14)) | O14: =IF(OR(G14="",K14="",H14="",L14=""),"",0.60+0.20*((G14+K14)/2)+0.20*((H14+L14)/2)) | P14: =IF(OR(B14="",N14="",O14=""),"",B14*N14*O14) | Q14: =IF(B14="", "", B14*(0.50*G14+0.20*H14+0.20*F14+0.10*(1-I14/25))) | R14: =IF(B14="", "", B14*(0.50*K14+0.20*L14+0.20*J14+0.10*(1-M14/25))) | S14: =IFERROR(VLOOKUP(D14,AnswerBank_v5!$A$2:$AP$311,29,FALSE),"") | T14: =IFERROR(VLOOKUP(E14,AnswerBank_v5!$A$2:$AP$311,29,FALSE),"")
A15: 6 | B15: =VLOOKUP(A15,QuestionWeights_v4!$A$2:$C$61,3,FALSE) | C15: =IFERROR(VLOOKUP(D15,AnswerBank_v5!$A$2:$AP$311,6,FALSE),"") | F15: =IFERROR(VLOOKUP(D15,AnswerBank_v5!$A$2:$AP$311,15,FALSE)/10,"") | G15: =IFERROR(VLOOKUP(D15,AnswerBank_v5!$A$2:$AP$311,14,FALSE)/10,"") | H15: =IFERROR(VLOOKUP(D15,AnswerBank_v5!$A$2:$AP$311,16,FALSE)/10,"") | I15: =IFERROR(VLOOKUP(D15,AnswerBank_v5!$A$2:$AP$311,31,FALSE),0) | J15: =IFERROR(VLOOKUP(E15,AnswerBank_v5!$A$2:$AP$311,15,FALSE)/10,"") | K15: =IFERROR(VLOOKUP(E15,AnswerBank_v5!$A$2:$AP$311,14,FALSE)/10,"") | L15: =IFERROR(VLOOKUP(E15,AnswerBank_v5!$A$2:$AP$311,16,FALSE)/10,"") | M15: =IFERROR(VLOOKUP(E15,AnswerBank_v5!$A$2:$AP$311,31,FALSE),0) | N15: =IF(OR(F15="",J15=""),"",1-ABS(F15-J15)) | O15: =IF(OR(G15="",K15="",H15="",L15=""),"",0.60+0.20*((G15+K15)/2)+0.20*((H15+L15)/2)) | P15: =IF(OR(B15="",N15="",O15=""),"",B15*N15*O15) | Q15: =IF(B15="", "", B15*(0.50*G15+0.20*H15+0.20*F15+0.10*(1-I15/25))) | R15: =IF(B15="", "", B15*(0.50*K15+0.20*L15+0.20*J15+0.10*(1-M15/25))) | S15: =IFERROR(VLOOKUP(D15,AnswerBank_v5!$A$2:$AP$311,29,FALSE),"") | T15: =IFERROR(VLOOKUP(E15,AnswerBank_v5!$A$2:$AP$311,29,FALSE),"")
A16: 7 | B16: =VLOOKUP(A16,QuestionWeights_v4!$A$2:$C$61,3,FALSE) | C16: =IFERROR(VLOOKUP(D16,AnswerBank_v5!$A$2:$AP$311,6,FALSE),"") | F16: =IFERROR(VLOOKUP(D16,AnswerBank_v5!$A$2:$AP$311,15,FALSE)/10,"") | G16: =IFERROR(VLOOKUP(D16,AnswerBank_v5!$A$2:$AP$311,14,FALSE)/10,"") | H16: =IFERROR(VLOOKUP(D16,AnswerBank_v5!$A$2:$AP$311,16,FALSE)/10,"") | I16: =IFERROR(VLOOKUP(D16,AnswerBank_v5!$A$2:$AP$311,31,FALSE),0) | J16: =IFERROR(VLOOKUP(E16,AnswerBank_v5!$A$2:$AP$311,15,FALSE)/10,"") | K16: =IFERROR(VLOOKUP(E16,AnswerBank_v5!$A$2:$AP$311,14,FALSE)/10,"") | L16: =IFERROR(VLOOKUP(E16,AnswerBank_v5!$A$2:$AP$311,16,FALSE)/10,"") | M16: =IFERROR(VLOOKUP(E16,AnswerBank_v5!$A$2:$AP$311,31,FALSE),0) | N16: =IF(OR(F16="",J16=""),"",1-ABS(F16-J16)) | O16: =IF(OR(G16="",K16="",H16="",L16=""),"",0.60+0.20*((G16+K16)/2)+0.20*((H16+L16)/2)) | P16: =IF(OR(B16="",N16="",O16=""),"",B16*N16*O16) | Q16: =IF(B16="", "", B16*(0.50*G16+0.20*H16+0.20*F16+0.10*(1-I16/25))) | R16: =IF(B16="", "", B16*(0.50*K16+0.20*L16+0.20*J16+0.10*(1-M16/25))) | S16: =IFERROR(VLOOKUP(D16,AnswerBank_v5!$A$2:$AP$311,29,FALSE),"") | T16: =IFERROR(VLOOKUP(E16,AnswerBank_v5!$A$2:$AP$311,29,FALSE),"")
A17: 8 | B17: =VLOOKUP(A17,QuestionWeights_v4!$A$2:$C$61,3,FALSE) | C17: =IFERROR(VLOOKUP(D17,AnswerBank_v5!$A$2:$AP$311,6,FALSE),"") | F17: =IFERROR(VLOOKUP(D17,AnswerBank_v5!$A$2:$AP$311,15,FALSE)/10,"") | G17: =IFERROR(VLOOKUP(D17,AnswerBank_v5!$A$2:$AP$311,14,FALSE)/10,"") | H17: =IFERROR(VLOOKUP(D17,AnswerBank_v5!$A$2:$AP$311,16,FALSE)/10,"") | I17: =IFERROR(VLOOKUP(D17,AnswerBank_v5!$A$2:$AP$311,31,FALSE),0) | J17: =IFERROR(VLOOKUP(E17,AnswerBank_v5!$A$2:$AP$311,15,FALSE)/10,"") | K17: =IFERROR(VLOOKUP(E17,AnswerBank_v5!$A$2:$AP$311,14,FALSE)/10,"") | L17: =IFERROR(VLOOKUP(E17,AnswerBank_v5!$A$2:$AP$311,16,FALSE)/10,"") | M17: =IFERROR(VLOOKUP(E17,AnswerBank_v5!$A$2:$AP$311,31,FALSE),0) | N17: =IF(OR(F17="",J17=""),"",1-ABS(F17-J17)) | O17: =IF(OR(G17="",K17="",H17="",L17=""),"",0.60+0.20*((G17+K17)/2)+0.20*((H17+L17)/2)) | P17: =IF(OR(B17="",N17="",O17=""),"",B17*N17*O17) | Q17: =IF(B17="", "", B17*(0.50*G17+0.20*H17+0.20*F17+0.10*(1-I17/25))) | R17: =IF(B17="", "", B17*(0.50*K17+0.20*L17+0.20*J17+0.10*(1-M17/25))) | S17: =IFERROR(VLOOKUP(D17,AnswerBank_v5!$A$2:$AP$311,29,FALSE),"") | T17: =IFERROR(VLOOKUP(E17,AnswerBank_v5!$A$2:$AP$311,29,FALSE),"")
A18: 9 | B18: =VLOOKUP(A18,QuestionWeights_v4!$A$2:$C$61,3,FALSE) | C18: =IFERROR(VLOOKUP(D18,AnswerBank_v5!$A$2:$AP$311,6,FALSE),"") | F18: =IFERROR(VLOOKUP(D18,AnswerBank_v5!$A$2:$AP$311,15,FALSE)/10,"") | G18: =IFERROR(VLOOKUP(D18,AnswerBank_v5!$A$2:$AP$311,14,FALSE)/10,"") | H18: =IFERROR(VLOOKUP(D18,AnswerBank_v5!$A$2:$AP$311,16,FALSE)/10,"") | I18: =IFERROR(VLOOKUP(D18,AnswerBank_v5!$A$2:$AP$311,31,FALSE),0) | J18: =IFERROR(VLOOKUP(E18,AnswerBank_v5!$A$2:$AP$311,15,FALSE)/10,"") | K18: =IFERROR(VLOOKUP(E18,AnswerBank_v5!$A$2:$AP$311,14,FALSE)/10,"") | L18: =IFERROR(VLOOKUP(E18,AnswerBank_v5!$A$2:$AP$311,16,FALSE)/10,"") | M18: =IFERROR(VLOOKUP(E18,AnswerBank_v5!$A$2:$AP$311,31,FALSE),0) | N18: =IF(OR(F18="",J18=""),"",1-ABS(F18-J18)) | O18: =IF(OR(G18="",K18="",H18="",L18=""),"",0.60+0.20*((G18+K18)/2)+0.20*((H18+L18)/2)) | P18: =IF(OR(B18="",N18="",O18=""),"",B18*N18*O18) | Q18: =IF(B18="", "", B18*(0.50*G18+0.20*H18+0.20*F18+0.10*(1-I18/25))) | R18: =IF(B18="", "", B18*(0.50*K18+0.20*L18+0.20*J18+0.10*(1-M18/25))) | S18: =IFERROR(VLOOKUP(D18,AnswerBank_v5!$A$2:$AP$311,29,FALSE),"") | T18: =IFERROR(VLOOKUP(E18,AnswerBank_v5!$A$2:$AP$311,29,FALSE),"")
A19: 10 | B19: =VLOOKUP(A19,QuestionWeights_v4!$A$2:$C$61,3,FALSE) | C19: =IFERROR(VLOOKUP(D19,AnswerBank_v5!$A$2:$AP$311,6,FALSE),"") | F19: =IFERROR(VLOOKUP(D19,AnswerBank_v5!$A$2:$AP$311,15,FALSE)/10,"") | G19: =IFERROR(VLOOKUP(D19,AnswerBank_v5!$A$2:$AP$311,14,FALSE)/10,"") | H19: =IFERROR(VLOOKUP(D19,AnswerBank_v5!$A$2:$AP$311,16,FALSE)/10,"") | I19: =IFERROR(VLOOKUP(D19,AnswerBank_v5!$A$2:$AP$311,31,FALSE),0) | J19: =IFERROR(VLOOKUP(E19,AnswerBank_v5!$A$2:$AP$311,15,FALSE)/10,"") | K19: =IFERROR(VLOOKUP(E19,AnswerBank_v5!$A$2:$AP$311,14,FALSE)/10,"") | L19: =IFERROR(VLOOKUP(E19,AnswerBank_v5!$A$2:$AP$311,16,FALSE)/10,"") | M19: =IFERROR(VLOOKUP(E19,AnswerBank_v5!$A$2:$AP$311,31,FALSE),0) | N19: =IF(OR(F19="",J19=""),"",1-ABS(F19-J19)) | O19: =IF(OR(G19="",K19="",H19="",L19=""),"",0.60+0.20*((G19+K19)/2)+0.20*((H19+L19)/2)) | P19: =IF(OR(B19="",N19="",O19=""),"",B19*N19*O19) | Q19: =IF(B19="", "", B19*(0.50*G19+0.20*H19+0.20*F19+0.10*(1-I19/25))) | R19: =IF(B19="", "", B19*(0.50*K19+0.20*L19+0.20*J19+0.10*(1-M19/25))) | S19: =IFERROR(VLOOKUP(D19,AnswerBank_v5!$A$2:$AP$311,29,FALSE),"") | T19: =IFERROR(VLOOKUP(E19,AnswerBank_v5!$A$2:$AP$311,29,FALSE),"")
A20: 11 | B20: =VLOOKUP(A20,QuestionWeights_v4!$A$2:$C$61,3,FALSE) | C20: =IFERROR(VLOOKUP(D20,AnswerBank_v5!$A$2:$AP$311,6,FALSE),"") | F20: =IFERROR(VLOOKUP(D20,AnswerBank_v5!$A$2:$AP$311,15,FALSE)/10,"") | G20: =IFERROR(VLOOKUP(D20,AnswerBank_v5!$A$2:$AP$311,14,FALSE)/10,"") | H20: =IFERROR(VLOOKUP(D20,AnswerBank_v5!$A$2:$AP$311,16,FALSE)/10,"") | I20: =IFERROR(VLOOKUP(D20,AnswerBank_v5!$A$2:$AP$311,31,FALSE),0) | J20: =IFERROR(VLOOKUP(E20,AnswerBank_v5!$A$2:$AP$311,15,FALSE)/10,"") | K20: =IFERROR(VLOOKUP(E20,AnswerBank_v5!$A$2:$AP$311,14,FALSE)/10,"") | L20: =IFERROR(VLOOKUP(E20,AnswerBank_v5!$A$2:$AP$311,16,FALSE)/10,"") | M20: =IFERROR(VLOOKUP(E20,AnswerBank_v5!$A$2:$AP$311,31,FALSE),0) | N20: =IF(OR(F20="",J20=""),"",1-ABS(F20-J20)) | O20: =IF(OR(G20="",K20="",H20="",L20=""),"",0.60+0.20*((G20+K20)/2)+0.20*((H20+L20)/2)) | P20: =IF(OR(B20="",N20="",O20=""),"",B20*N20*O20) | Q20: =IF(B20="", "", B20*(0.50*G20+0.20*H20+0.20*F20+0.10*(1-I20/25))) | R20: =IF(B20="", "", B20*(0.50*K20+0.20*L20+0.20*J20+0.10*(1-M20/25))) | S20: =IFERROR(VLOOKUP(D20,AnswerBank_v5!$A$2:$AP$311,29,FALSE),"") | T20: =IFERROR(VLOOKUP(E20,AnswerBank_v5!$A$2:$AP$311,29,FALSE),"")
A21: 12 | B21: =VLOOKUP(A21,QuestionWeights_v4!$A$2:$C$61,3,FALSE) | C21: =IFERROR(VLOOKUP(D21,AnswerBank_v5!$A$2:$AP$311,6,FALSE),"") | F21: =IFERROR(VLOOKUP(D21,AnswerBank_v5!$A$2:$AP$311,15,FALSE)/10,"") | G21: =IFERROR(VLOOKUP(D21,AnswerBank_v5!$A$2:$AP$311,14,FALSE)/10,"") | H21: =IFERROR(VLOOKUP(D21,AnswerBank_v5!$A$2:$AP$311,16,FALSE)/10,"") | I21: =IFERROR(VLOOKUP(D21,AnswerBank_v5!$A$2:$AP$311,31,FALSE),0) | J21: =IFERROR(VLOOKUP(E21,AnswerBank_v5!$A$2:$AP$311,15,FALSE)/10,"") | K21: =IFERROR(VLOOKUP(E21,AnswerBank_v5!$A$2:$AP$311,14,FALSE)/10,"") | L21: =IFERROR(VLOOKUP(E21,AnswerBank_v5!$A$2:$AP$311,16,FALSE)/10,"") | M21: =IFERROR(VLOOKUP(E21,AnswerBank_v5!$A$2:$AP$311,31,FALSE),0) | N21: =IF(OR(F21="",J21=""),"",1-ABS(F21-J21)) | O21: =IF(OR(G21="",K21="",H21="",L21=""),"",0.60+0.20*((G21+K21)/2)+0.20*((H21+L21)/2)) | P21: =IF(OR(B21="",N21="",O21=""),"",B21*N21*O21) | Q21: =IF(B21="", "", B21*(0.50*G21+0.20*H21+0.20*F21+0.10*(1-I21/25))) | R21: =IF(B21="", "", B21*(0.50*K21+0.20*L21+0.20*J21+0.10*(1-M21/25))) | S21: =IFERROR(VLOOKUP(D21,AnswerBank_v5!$A$2:$AP$311,29,FALSE),"") | T21: =IFERROR(VLOOKUP(E21,AnswerBank_v5!$A$2:$AP$311,29,FALSE),"")
... A59: 50 | B59: =VLOOKUP(A59,QuestionWeights_v4!$A$2:$C$61,3,FALSE) | C59: =IFERROR(VLOOKUP(D59,AnswerBank_v5!$A$2:$AP$311,6,FALSE),"") | F59: =IFERROR(VLOOKUP(D59,AnswerBank_v5!$A$2:$AP$311,15,FALSE)/10,"") | G59: =IFERROR(VLOOKUP(D59,AnswerBank_v5!$A$2:$AP$311,14,FALSE)/10,"") | H59: =IFERROR(VLOOKUP(D59,AnswerBank_v5!$A$2:$AP$311,16,FALSE)/10,"") | I59: =IFERROR(VLOOKUP(D59,AnswerBank_v5!$A$2:$AP$311,31,FALSE),0) | J59: =IFERROR(VLOOKUP(E59,AnswerBank_v5!$A$2:$AP$311,15,FALSE)/10,"") | K59: =IFERROR(VLOOKUP(E59,AnswerBank_v5!$A$2:$AP$311,14,FALSE)/10,"") | L59: =IFERROR(VLOOKUP(E59,AnswerBank_v5!$A$2:$AP$311,16,FALSE)/10,"") | M59: =IFERROR(VLOOKUP(E59,AnswerBank_v5!$A$2:$AP$311,31,FALSE),0) | N59: =IF(OR(F59="",J59=""),"",1-ABS(F59-J59)) | O59: =IF(OR(G59="",K59="",H59="",L59=""),"",0.60+0.20*((G59+K59)/2)+0.20*((H59+L59)/2)) | P59: =IF(OR(B59="",N59="",O59=""),"",B59*N59*O59) | Q59: =IF(B59="", "", B59*(0.50*G59+0.20*H59+0.20*F59+0.10*(1-I59/25))) | R59: =IF(B59="", "", B59*(0.50*K59+0.20*L59+0.20*J59+0.10*(1-M59/25))) | S59: =IFERROR(VLOOKUP(D59,AnswerBank_v5!$A$2:$AP$311,29,FALSE),"") | T59: =IFERROR(VLOOKUP(E59,AnswerBank_v5!$A$2:$AP$311,29,FALSE),"")
A61: Summary
A62: TotalWeight | B62: =SUM(B10:B59)
A63: BehaviorCore (0..1) | B63: =0.22*B70+0.20*B71+0.20*B72+0.14*B73+0.12*B74+0.12*B75
A64: Readiness_A (0..100) | B64: =100*SUM(Q10:Q59)/SUM(B10:B59)
A65: Readiness_B (0..100) | B65: =100*SUM(R10:R59)/SUM(B10:B59)
A66: ClusterPenaltySum_A | B66: =SUM(I10:I59)
A67: ClusterPenaltySum_B | B67: =SUM(M10:M59)
A69: Dimension | B69: Score (0..1)
A70: CommunicationHealth | B70: =IFERROR(SUMIF($C$10:$C$59,A70,$P$10:$P$59)/SUMIF($C$10:$C$59,A70,$B$10:$B$59),0)
A71: ConflictRepair | B71: =IFERROR(SUMIF($C$10:$C$59,A71,$P$10:$P$59)/SUMIF($C$10:$C$59,A71,$B$10:$B$59),0) | C71: answer_id_B | D71: shadowRiskA | E71: integrityA | F71: shadowTypeA | G71: shadowRiskB | H71: integrityB | I71: shadowTypeB
A72: EmotionalRegulation | B72: =IFERROR(SUMIF($C$10:$C$59,A72,$P$10:$P$59)/SUMIF($C$10:$C$59,A72,$B$10:$B$59),0) | D72: =IFERROR(VLOOKUP(B72,AnswerBank_v5!$A$2:$AP$311,21,FALSE)/10,0) | E72: =IFERROR(VLOOKUP(B72,AnswerBank_v5!$A$2:$AP$311,36,FALSE),"") | F72: =IFERROR(VLOOKUP(B72,AnswerBank_v5!$A$2:$AP$311,19,FALSE),"") | G72: =IFERROR(VLOOKUP(C72,AnswerBank_v5!$A$2:$AP$311,21,FALSE)/10,0) | H72: =IFERROR(VLOOKUP(C72,AnswerBank_v5!$A$2:$AP$311,36,FALSE),"") | I72: =IFERROR(VLOOKUP(C72,AnswerBank_v5!$A$2:$AP$311,19,FALSE),"")
A73: ValuesLifestyle | B73: =IFERROR(SUMIF($C$10:$C$59,A73,$P$10:$P$59)/SUMIF($C$10:$C$59,A73,$B$10:$B$59),0) | D73: =IFERROR(VLOOKUP(B73,AnswerBank_v5!$A$2:$AP$311,21,FALSE)/10,0) | E73: =IFERROR(VLOOKUP(B73,AnswerBank_v5!$A$2:$AP$311,36,FALSE),"") | F73: =IFERROR(VLOOKUP(B73,AnswerBank_v5!$A$2:$AP$311,19,FALSE),"") | G73: =IFERROR(VLOOKUP(C73,AnswerBank_v5!$A$2:$AP$311,21,FALSE)/10,0) | H73: =IFERROR(VLOOKUP(C73,AnswerBank_v5!$A$2:$AP$311,36,FALSE),"") | I73: =IFERROR(VLOOKUP(C73,AnswerBank_v5!$A$2:$AP$311,19,FALSE),"")
A74: CommitmentPace | B74: =IFERROR(SUMIF($C$10:$C$59,A74,$P$10:$P$59)/SUMIF($C$10:$C$59,A74,$B$10:$B$59),0) | D74: =IFERROR(VLOOKUP(B74,AnswerBank_v5!$A$2:$AP$311,21,FALSE)/10,0) | E74: =IFERROR(VLOOKUP(B74,AnswerBank_v5!$A$2:$AP$311,36,FALSE),"") | F74: =IFERROR(VLOOKUP(B74,AnswerBank_v5!$A$2:$AP$311,19,FALSE),"") | G74: =IFERROR(VLOOKUP(C74,AnswerBank_v5!$A$2:$AP$311,21,FALSE)/10,0) | H74: =IFERROR(VLOOKUP(C74,AnswerBank_v5!$A$2:$AP$311,36,FALSE),"") | I74: =IFERROR(VLOOKUP(C74,AnswerBank_v5!$A$2:$AP$311,19,FALSE),"")
A75: EmotionalNeeds | B75: =IFERROR(SUMIF($C$10:$C$59,A75,$P$10:$P$59)/SUMIF($C$10:$C$59,A75,$B$10:$B$59),0) | D75: =IFERROR(VLOOKUP(B75,AnswerBank_v5!$A$2:$AP$311,21,FALSE)/10,0) | E75: =IFERROR(VLOOKUP(B75,AnswerBank_v5!$A$2:$AP$311,36,FALSE),"") | F75: =IFERROR(VLOOKUP(B75,AnswerBank_v5!$A$2:$AP$311,19,FALSE),"") | G75: =IFERROR(VLOOKUP(C75,AnswerBank_v5!$A$2:$AP$311,21,FALSE)/10,0) | H75: =IFERROR(VLOOKUP(C75,AnswerBank_v5!$A$2:$AP$311,36,FALSE),"") | I75: =IFERROR(VLOOKUP(C75,AnswerBank_v5!$A$2:$AP$311,19,FALSE),"")
A76: 55 | D76: =IFERROR(VLOOKUP(B76,AnswerBank_v5!$A$2:$AP$311,21,FALSE)/10,0) | E76: =IFERROR(VLOOKUP(B76,AnswerBank_v5!$A$2:$AP$311,36,FALSE),"") | F76: =IFERROR(VLOOKUP(B76,AnswerBank_v5!$A$2:$AP$311,19,FALSE),"") | G76: =IFERROR(VLOOKUP(C76,AnswerBank_v5!$A$2:$AP$311,21,FALSE)/10,0) | H76: =IFERROR(VLOOKUP(C76,AnswerBank_v5!$A$2:$AP$311,36,FALSE),"") | I76: =IFERROR(VLOOKUP(C76,AnswerBank_v5!$A$2:$AP$311,19,FALSE),"")
A77: 56 | D77: =IFERROR(VLOOKUP(B77,AnswerBank_v5!$A$2:$AP$311,21,FALSE)/10,0) | E77: =IFERROR(VLOOKUP(B77,AnswerBank_v5!$A$2:$AP$311,36,FALSE),"") | F77: =IFERROR(VLOOKUP(B77,AnswerBank_v5!$A$2:$AP$311,19,FALSE),"") | G77: =IFERROR(VLOOKUP(C77,AnswerBank_v5!$A$2:$AP$311,21,FALSE)/10,0) | H77: =IFERROR(VLOOKUP(C77,AnswerBank_v5!$A$2:$AP$311,36,FALSE),"") | I77: =IFERROR(VLOOKUP(C77,AnswerBank_v5!$A$2:$AP$311,19,FALSE),"")
A78: 57 | D78: =IFERROR(VLOOKUP(B78,AnswerBank_v5!$A$2:$AP$311,21,FALSE)/10,0) | E78: =IFERROR(VLOOKUP(B78,AnswerBank_v5!$A$2:$AP$311,36,FALSE),"") | F78: =IFERROR(VLOOKUP(B78,AnswerBank_v5!$A$2:$AP$311,19,FALSE),"") | G78: =IFERROR(VLOOKUP(C78,AnswerBank_v5!$A$2:$AP$311,21,FALSE)/10,0) | H78: =IFERROR(VLOOKUP(C78,AnswerBank_v5!$A$2:$AP$311,36,FALSE),"") | I78: =IFERROR(VLOOKUP(C78,AnswerBank_v5!$A$2:$AP$311,19,FALSE),"")
A79: 58 | D79: =IFERROR(VLOOKUP(B79,AnswerBank_v5!$A$2:$AP$311,21,FALSE)/10,0) | E79: =IFERROR(VLOOKUP(B79,AnswerBank_v5!$A$2:$AP$311,36,FALSE),"") | F79: =IFERROR(VLOOKUP(B79,AnswerBank_v5!$A$2:$AP$311,19,FALSE),"") | G79: =IFERROR(VLOOKUP(C79,AnswerBank_v5!$A$2:$AP$311,21,FALSE)/10,0) | H79: =IFERROR(VLOOKUP(C79,AnswerBank_v5!$A$2:$AP$311,36,FALSE),"") | I79: =IFERROR(VLOOKUP(C79,AnswerBank_v5!$A$2:$AP$311,19,FALSE),"")
A80: 59 | D80: =IFERROR(VLOOKUP(B80,AnswerBank_v5!$A$2:$AP$311,21,FALSE)/10,0) | E80: =IFERROR(VLOOKUP(B80,AnswerBank_v5!$A$2:$AP$311,36,FALSE),"") | F80: =IFERROR(VLOOKUP(B80,AnswerBank_v5!$A$2:$AP$311,19,FALSE),"") | G80: =IFERROR(VLOOKUP(C80,AnswerBank_v5!$A$2:$AP$311,21,FALSE)/10,0) | H80: =IFERROR(VLOOKUP(C80,AnswerBank_v5!$A$2:$AP$311,36,FALSE),"") | I80: =IFERROR(VLOOKUP(C80,AnswerBank_v5!$A$2:$AP$311,19,FALSE),"")
A81: 60 | D81: =IFERROR(VLOOKUP(B81,AnswerBank_v5!$A$2:$AP$311,21,FALSE)/10,0) | E81: =IFERROR(VLOOKUP(B81,AnswerBank_v5!$A$2:$AP$311,36,FALSE),"") | F81: =IFERROR(VLOOKUP(B81,AnswerBank_v5!$A$2:$AP$311,19,FALSE),"") | G81: =IFERROR(VLOOKUP(C81,AnswerBank_v5!$A$2:$AP$311,21,FALSE)/10,0) | H81: =IFERROR(VLOOKUP(C81,AnswerBank_v5!$A$2:$AP$311,36,FALSE),"") | I81: =IFERROR(VLOOKUP(C81,AnswerBank_v5!$A$2:$AP$311,19,FALSE),"")
A83: ShadowIntensity_A | B83: =AVERAGE(D72:D81)
...

Sheet FinalScores_v4
A1: Final Scores v4 (deterministic prior, using all matrices)
A3: Pull from TestHarness_v4 | D3: Manual selections (use dropdowns in Excel)
A4: BehaviorCore | B4: =TestHarness_v4!B63 | D4: PrimaryArchetype_A | E4: REGULATED
A5: ClusterPenaltySum_A | B5: =TestHarness_v4!B66 | D5: SecondaryArchetype_A | E5: TRANSLATOR
A6: ClusterPenaltySum_B | B6: =TestHarness_v4!B67 | D6: PrimaryArchetype_B | E6: REGULATED
A7: ShadowIntensity_A | B7: =TestHarness_v4!B83 | D7: SecondaryArchetype_B | E7: ANALYZER
A8: ShadowIntensity_B | B8: =TestHarness_v4!B84
A9: IntegrityFlags_A | B9: =TestHarness_v4!B85 | D9: CommStyle_A | E9: COMM_Direct
A10: IntegrityFlags_B | B10: =TestHarness_v4!B86 | D10: CommStyle_B | E10: COMM_Emotional
A11: PrimaryShadow_A | B11: =TestHarness_v4!B87 | D11: RegStyle_A | E11: REG_CoRegulator
A12: PrimaryShadow_B | B12: =TestHarness_v4!B88 | D12: RegStyle_B | E12: REG_SelfSoother
D13: LoveLang_A | E13: LL_Words
A14: CommHealth | B14: =TestHarness_v4!B70 | D14: LoveLang_B | E14: LL_Touch
A15: ConflictRepair | B15: =TestHarness_v4!B71
A16: EmotionalReg | B16: =TestHarness_v4!B72 | D16: CommConflictNorm | E16: =IF(E9<E10,E9&"+" &E10,E10&"+" &E9) | F16: =IFERROR((VLOOKUP(E16,CommLookup_v4!$A$2:$B$16,2,FALSE)-2)/7,0.5)
A17: CommitmentPace | B17: =TestHarness_v4!B74 | D17: RegulationNorm | E17: =IF(E11<E12,E11&"+" &E12,E12&"+" &E11) | F17: =IFERROR((VLOOKUP(E17,RegLookup_v4!$A$2:$B$11,2,FALSE)-3)/7,0.5)
D18: LoveNorm | E18: =IF(E13<E14,E13&"+" &E14,E14&"+" &E13) | F18: =IFERROR((VLOOKUP(E18,LoveLookup_v4!$A$2:$B$16,2,FALSE)-5)/5,0.6)
D20: PP | E20: =IFERROR(VLOOKUP(E4&"|"&E6,ArchetypeLookup_v4!$A$2:$B$101,2,FALSE),7)
D21: PS | E21: =IFERROR(VLOOKUP(E4&"|"&E7,ArchetypeLookup_v4!$A$2:$B$101,2,FALSE),7)
D22: SP | E22: =IFERROR(VLOOKUP(E5&"|"&E6,ArchetypeLookup_v4!$A$2:$B$101,2,FALSE),7)
D23: SS | E23: =IFERROR(VLOOKUP(E5&"|"&E7,ArchetypeLookup_v4!$A$2:$B$101,2,FALSE),7)
D24: A (0..1) | E24: =((0.50*E20+0.20*E21+0.20*E22+0.10*E23)-2)/7
D26: ShadowKey | E26: =UPPER(SUBSTITUTE(SUBSTITUTE(B11," ",""),"-","")) | F26: =UPPER(SUBSTITUTE(SUBSTITUTE(B12," ",""),"-","")) | G26: =IF(E26<F26,E26&"_"&F26,F26&"_"&E26)
D27: ShadowScore | E27: =IFERROR(VLOOKUP(G26,ShadowLookup_v4!$A$2:$B$37,2,FALSE),3)
